Workbook
Name Logos: INDEX(Rates!$D$23:$D$45,MATCH(QUOTATION!$B$29,Rates!$C$23:$C$45,0))
Name Logos1: INDEX(Rates!$D$23:$D$45,MATCH(QUOTATION!$D$29,Rates!$C$23:$C$45,0))
Name Logos2: INDEX(Rates!$D$23:$D$45,MATCH(QUOTATION!$F$29,Rates!$C$23:$C$45,0))
Name Logos3: INDEX(Rates!$D$23:$D$45,MATCH(QUOTATION!#REF!,Rates!$C$23:$C$45,0))
Name Logos4: INDEX(Rates!$D$23:$D$45,MATCH(QUOTATION!#REF!,Rates!$C$23:$C$45,0))
Name Logos5: INDEX(Rates!$D$23:$D$45,MATCH(QUOTATION!#REF!,Rates!$C$23:$C$45,0))

Sheet Sheet1

Sheet QUOTATION
A4: Product Type | B4: Private Car Comprehensive policy
A5: Insured | B5: PATIL RAIL INFRASTRUCTURE PVT LTD
A6: Reg No | B6: TG 09 A 4879
A7: Engine No. | B7: 46354451-4314246
A8: Chassis No. | B8: MAT631752RWE21447
A9: Mfg.Yr | B9: 45474 | C9: =DATEDIF(B9, B23, "Y") & " years, " & DATEDIF(B9, B23, "YM") & " months, " & DATEDIF(B9, B23, "MD") & " days" -> 1 years, 11 months, 13 days
A10: Previous Insurer | B10: 6204855898 00 00
A11: Previous insurer policy number | B11: Tata AIG General Insurance Company Limited
A12: Ex Showroom Price | B12: 21386200
A13: Seating Capacity | B13: 6
A14: LAST YEAR NCB | B14: 0.2
A15: CLAIM | B15: NO
A16: Gross Vehicle Weight (GCV)/Cubic Capacity | B16: 1956 | C16: PRIVATE CAR Above 1500 cc ZONE A
A17: RENEWAL | B17: NO
A18: Make | B18: TATA MOTORS
A19: Model | B19: NEW SAFARI ACCOMPLISHED PLUS DARK 6S AT
A20: FUEL | B20: Diesel
A21: ZONE | B21: PRIVATE CAR 0-5 ZONE A
A22: Policy Period | B22: Policy Start date | C22: Policy End date
B23: 46187 | C23: =B23+364 -> 46551
H24: LAST YEAR
A29: Insurers | B29: Kotak General Insurance Company Ltd | D29: Go Digit General Insurance Limited | F29: HDFC ERGO General Insurance Company Limited | H29: Tata AIG General Insurance Company Limited
A31: Total Insured Declared Value (IDV) | C31: =C32+C33 -> 2340450 | E31: =E32+E33 -> 2296560 | G31: =G32+G33 -> 2340450 | I31: =I32+I33 -> 2600500
A32: Insured Declared Value (IDV) | C32: 2340450 | E32: 2296560 | G32: 2340450 | I32: 2600500
A33: Bi-Fuel Kit (CNG/LPG)(IDV) | C33: 0 | E33: 0 | G33: 0 | I33: 0
A34: Rate | C34: =INDEX(Rates!$M$6:$AG$26,Rates!$L$3,Rates!$K$5) -> 0.0344 | E34: =INDEX(Rates!$M$6:$AG$26,Rates!$L$3,Rates!$K$5) -> 0.0344 | G34: =INDEX(Rates!$M$6:$AG$26,Rates!$L$3,Rates!$K$5) -> 0.0344 | I34: =INDEX(Rates!$M$6:$AG$26,Rates!$L$3,Rates!$K$5) -> 0.0344
A35: OD premium | C35: =(C32*C34)+(4%*C33) -> 80511.48 | E35: =E32*E34 -> 79001.664 | G35: =G32*G34 -> 80511.48 | I35: =I32*I34 -> 89457.2
A36: Detariff discount | B36: 0.9 | C36: =C35*B36 -> 72460.332 | D36: 0.85 | E36: =E35*D36 -> 67151.414 | F36: 0.9 | G36: =G35*F36 -> 72460.332 | H36: 0.85 | I36: =I35*H36 -> 76038.62
A37: OD premium after detariff discount | C37: =C35-C36 -> 8051.148 | E37: =E35-E36 -> 11850.25 | G37: =G35-G36 -> 8051.148 | I37: =I35-I36 -> 13418.58
A38: Add: CNG 4% | B38: 0 | C38: =IF($B$20="Petrol/internal CNG",(((C31*C34)+C40)*5)*(100%-B36)%,(IF($B$20="Petrol/External CNG",(C33*4%)*(100%-B36),0))) -> 0 | D38: 0 | E38: =IF($B$20="Petrol/internal CNG",(((E31*E34)+E40)*5)*(100%-D36)%,(IF($B$20="Petrol/External CNG",(E33*4%)*(100%-D36),0))) -> 0 | F38: 0 | G38: =IF($B$20="Petrol/internal CNG",(((G31*G34)+G40)*5)*(100%-F36)%,(IF($B$20="Petrol/External CNG",(G33*4%)*(100%-F36),0))) -> 0 | H38: 0 | I38: =IF($B$20="Petrol/internal CNG",(((I31*I34)+I40)*5)*(100%-H36)%,(IF($B$20="Petrol/External CNG",(I33*4%)*(100%-H36),0))) -> 0
A39: Premium after CNG/EA | C39: =C37+C38 -> 8051.148 | E39: =E37+E38 -> 11850.25 | G39: =G37+G38 -> 8051.148 | I39: =I37+I38 -> 13418.58
A40: Add: Premium for Excess GVW | B40: 0 | C40: =IF($B$4="GOODS CARRYING VEHICLE (GCV) Comprehensive policy", IF($B$16<=12000, 0, (($B$16-12000)/100*27)*(100%-B36)), 0) -> 0 | D40: 0 | E40: =IF($B$4="GOODS CARRYING VEHICLE (GCV) Comprehensive policy", IF($B$16<=12000, 0, (($B$16-12000)/100*27)*(100%-D36)), 0) -> 0 | F40: 0 | G40: =IF($B$4="GOODS CARRYING VEHICLE (GCV) Comprehensive policy", IF($B$16<=12000, 0, (($B$16-12000)/100*27)*(100%-F36)), 0) -> 0 | H40: 0 | I40: =IF($B$4="GOODS CARRYING VEHICLE (GCV) Comprehensive policy", IF($B$16<=12000, 0, (($B$16-12000)/100*27)*(100%-H36)), 0) -> 0
A41: Basic OD premium after Excess GVW | C41: =C39+C40 -> 8051.148 | E41: =E39+E40 -> 11850.25 | G41: =G39+G40 -> 8051.148 | I41: =I39+I40 -> 13418.58
A42: Add: Overturning Risk Covered | B42: 0 | C42: 0 | D42: 0 | E42: 0 | F42: 0 | H42: 0 | I42: 0
A43: Basic OD premium after Overturning Risk | C43: =C41+C42 -> 8051.148 | E43: =E41+E42 -> 11850.25 | G43: =G41+G42 -> 8051.148 | I43: =I41+I42 -> 13418.58
A44: Add: IMT 23 Included | B44: 0 | C44: =IF(COUNTIF(C60:C60,"*IMT 23*")>0, 0.15*C37, 0) -> 0 | D44: 0 | E44: =IF(COUNTIF(E60:E60,"*IMT 23*")>0, 0.15*E37, 0) -> 0 | F44: 0 | G44: =IF(COUNTIF(G60:G60,"*IMT 23*")>0, 0.15*G37, 0) -> 0 | H44: 0 | I44: =IF(COUNTIF(I60:I60,"*IMT 23*")>0, 0.15*I37, 0) -> 0
A45: Basic OD premium before NCB | C45: =C43+C44 -> 8051.148 | E45: =E43+E44 -> 11850.25 | G45: =G43+G44 -> 8051.148 | I45: =I43+I44 -> 13418.58
A46: NCB Discount | B46: 0.25 | C46: =C45*B46 -> 2012.787 | D46: 0.25 | E46: =E45*D46 -> 2962.5624 | F46: 0.25 | G46: =G45*F46 -> 2012.787 | H46: 0.2 | I46: =I45*H46 -> 2683.716
A47: Net OD premium ( A ) | C47: =C45-C46 -> 6038.361 | E47: =E45-E46 -> 8887.6872 | G47: =G45-G46 -> 6038.361 | I47: =I45-I46 -> 10734.864
A48: Add: Third party premium | C48: 0 | E48: 0 | G48: 0 | I48: 0
...

Sheet Sheet2

Sheet Rates
E3: =MATCH(QUOTATION!B14,Rates!E5:E10,0) -> 2 | F3: 1 | G3: 2 | L3: =MATCH(QUOTATION!B21,Rates!L6:L26,0) -> 1
D4: =MATCH(QUOTATION!B15,Rates!F4:G4,0) -> 1 | E4: NCB | F4: NO | G4: YES | M4: 1 | N4: 2 | O4: 3 | P4: 4 | Q4: 5 | R4: 6 | S4: 7 | T4: 8 | U4: 9 | V4: 10 | W4: 11 | X4: 12
A5: Fuel | D5: 1 | E5: 0 | F5: 0.2 | G5: 0 | K5: =MATCH(QUOTATION!C16,Rates!M5:AG5,0) -> 3 | L5: YEAR | M5: PRIVATE CAR Below 1000 CC ZONE A | N5: PRIVATE CAR 1000--1500 cc ZONE A | O5: PRIVATE CAR Above 1500 cc ZONE A | P5: PRIVATE CAR <1000 CC ZONE B | Q5: PRIVATE CAR 1000><1500 CC ZONE B | R5: PRIVATE CAR >1500 CC ZONE B | S5: TWO WHEELER 0-150 ZONE A | T5: TWO WHEELER 150-350 ZONE A | U5: TWO WHEELER <350 ZONE A | V5: TWO WHEELER 0-150 ZONE B | W5: TWO WHEELER 150-350 ZONE B | X5: TWO WHEELER <350 ZONE B | Y5: GCV NOT 3W PUBLIC Zone A | Z5: GCV NOT 3W PUBLIC Zone B | AA5: GCV NOT 3W PUBLIC Zone C | AB5: GCV 3W PUBLIC Zone A | AC5: GCV 3W PUBLIC Zone B | AD5: GCV 3W PUBLIC Zone C | AE5: Misc Zone A | AF5: Misc Zone B | AG5: Misc Zone C
A6: Diesel | D6: 2 | E6: 0.2 | F6: 0.25 | G6: 0 | K6: 1 | L6: PRIVATE CAR 0-5 ZONE A | M6: 0.03127 | N6: 0.03283 | O6: 0.0344
A7: Petrol | D7: 3 | E7: 0.25 | F7: 0.35 | G7: 0 | I7: Business Type | K7: 2 | L7: PRIVATE CAR 5-10 ZONE A | M7: 0.03283 | N7: 0.03447 | O7: 0.03612
A8: Petrol/Internal CNG | D8: 4 | E8: 0.35 | F8: 0.45 | G8: 0 | I8: Renewal | K8: 3 | L8: PRIVATE CAR10-15 ZONE A | M8: 0.03529 | N8: 0.03529 | O8: 0.03698
A9: Petrol/External CNG | D9: 5 | E9: 0.45 | F9: 0.5 | G9: 0 | I9: Rollover | K9: 4 | L9: PRIVATE CAR 0-5 ZONE B | P9: 0.03039 | Q9: 0.03191 | R9: 0.03343
A10: Electric | D10: 6 | E10: 0.5 | F10: 0.5 | G10: 0 | I10: Used | K10: 5 | L10: PRIVATE CAR 5-10 ZONE B | P10: 0.03191 | Q10: 0.03351 | R10: 0.0351
K11: 6 | L11: PRIVATE CAR 10-15 ZONE B | P11: 0.03267 | Q11: 0.0343 | R11: 0.03594
K12: 7 | L12: TWO WHEELER 0-5 ZONE A | S12: 0.01708 | T12: 0.01793 | U12: 0.01879
K13: 8 | L13: TWO WHEELER 5-10 ZONE A | S13: 0.01793 | T13: 0.01883 | U13: 0.01973
K14: 9 | L14: TWO WHEELER 10-15 ZONE A | S14: 0.01836 | T14: 0.01928 | U14: 0.0202
K15: 10 | L15: TWO WHEELER 0-5 ZONE B | V15: 0.01676 | W15: 0.0176 | X15: 0.01884
K16: 11 | L16: TWO WHEELER 5-10 ZONE B | V16: 0.0176 | W16: 0.01848 | X16: 0.01936
K17: 12 | L17: TWO WHEELER 10-15 ZONE B | V17: 0.01802 | W17: 0.01892 | X17: 0.01982
L18: GCV NOT 3W PUBLIC Upto 5 Years | Y18: 0.01751 | Z18: 0.01743 | AA18: 0.01726
L19: GCV NOT 3W PUBLIC 5 to 7 Years | Y19: 0.01795 | Z19: 0.01787 | AA19: 0.0177
L20: GCV NOT 3W PUBLIC Above 7 Years | Y20: 0.01839 | Z20: 0.0183 | AA20: 0.01812
L21: GCV 3W PUBLIC Upto 5 Years | AB21: 0.01664 | AC21: 0.01656 | AD21: 0.0164
B22: S.No. | C22: Insurer Name | D22: Insurer Logo | L22: GCV 3W PUBLIC 5 to 7 Years | AB22: 0.01706 | AC22: 0.01697 | AD22: 0.01681
B23: 1 | C23: Go Digit General Insurance Limited | I23: Zero Depreciation | L23: GCV 3W PUBLIC Above 7 Years | AB23: 0.01747 | AC23: 0.01739 | AD23: 0.01722
B24: 2 | C24: SBI General Insurance Company Limited | I24: 24x7 Roadside Assistance | L24: Misc Upto 5 Years | AE24: 0.01208 | AF24: 0.01202 | AG24: 0.0119
B25: 3 | C25: Cholamandalam MS General Insurance Company Ltd | I25: Engine Protection Cover | L25: Misc 5 to 7 Years | AE25: 0.01238 | AF25: 0.01232 | AG25: 0.0122
B26: 4 | C26: HDFC ERGO General Insurance Company Limited | I26: Consumables | L26: Misc Above 7 Years | AE26: 0.01268 | AF26: 0.01262 | AG26: 0.0125
B27: 5 | C27: The Oriental Insurance Company Ltd | I27: Loss of Personal Belongings | M27: 2094 | N27: 3416 | O27: 7897 | P27: 2094 | Q27: 3416 | R27: 7897 | S27: 714 | T27: 1366 | U27: 2804 | V27: 714 | W27: 1366 | X27: 2804 | Y27: 0 | Z27: 0 | AA27: 0 | AB27: 0 | AC27: 0 | AD27: 0 | AE27: 7267 | AF27: 7267 | AG27: 7267
B28: 6 | C28: ICICI Lombard General Insurance Company Limited | I28: Key & Lock Replacement
B29: 7 | C29: Tata AIG General Insurance Company Limited | I29: Tyre Cover | M29: GVW | N29: TP Premium
B30: 8 | C30: Royal Sundaram General Insurance Co. Limited | I30: NCB Protect | M30: 0-7500 | N30: 16049
B31: 9 | C31: IFFCO-Tokio General Insurance Company Limited | I31: Return to Invoice Cover | M31: 7500-12000 | N31: 27186
B32: 10 | C32: National Insurance Company Limited | I32: Daily Allowance | M32: 12000-20000 | N32: 35313
B33: 11 | C33: Liberty General Insurance Ltd | I33: Emerg Transport & Hotel | M33: 20000-40000 | N33: 43950
B34: 12 | C34: Bajaj Allianz General Insurance Co. Ltd | I34: Passenger Assistance | M34: 40000-Above | N34: 44242
B35: 13 | C35: Reliance General Insurance Company Limited | I35: Personal Accident cover for owner driver
B36: 14 | C36: Universal Sompo General Insurance Co Ltd | I36: PA cover for Unnamed Passenger@Rs 1 Lakh Each
B37: 15 | C37: Shriram General Insurance Co. Ltd | I37: PA cover for Paid Driver
B38: 16 | C38: Future Generali India Insurance Company Ltd | I38: Legal Liability to Employees
B39: 17 | C39: The New India Assurance Co. Ltd | I39: Unlimited Claims
B40: 18 | C40: United India Insurance Company Ltd | I40: 2 claims per year
B41: 19 | C41: Kotak General Insurance Company Ltd | I41: IMT 23
B42: 20 | C42: Magma HDI General Insurance Company Limited | I42: Legal Liability to Paid Driver
...
